Workbook
Name f_obs: OFFSET(p_obs,0,0,COUNTA(l_obs),1)
Name f_site: OFFSET(p_site,0,0,COUNTA(l_site),1)
Name f_taxon: OFFSET(p_taxon,0,0,COUNTA(l_taxon),1)
Name l_obs: Utilisateurs!$D$2:$D$23
Name l_site: Sites!$A$2:$A$128
Name l_taxon: Taxons!$A$2:$A$511
Name p_obs: Utilisateurs!$D$2
Name p_site: Sites!$A$2
Name p_taxon: Taxons!$A$2

Sheet Comptage Décadaire
A1: ATTENTION à bien dupliquer toutes les cellules oranges pour chaque observation qui correspondera à un même relevé Les cellules plus foncées sont à remplir obligatoirement (ainsi que les cellules s'afficheant en rouge dans certains cas spécifique) / Les cellules en grises ne sont pas à remplir et se remplissent automatiquement
A2: id | B2: id_visit | C2: date | D2: site | E2: comptage_mensuel | F2: decade | G2: derangement | H2: type_derangement | I2: commeVisit | J2: nom_taxon | K2: nom_vernaculaire | L2: code_taxon | M2: heure | N2: observateu | O2: obs2 | P2: obs3 | Q2: obs4 | R2: obs5 | S2: statutObs | T2: effectif_total | U2: nb_ad_male | V2: nb_ad_femelle | W2: nb_ad | X2: nb_immat | Y2: nb_juv | Z2: precision_comptage | AA2: comportement | AB2: code_atlas | AC2: commeObser | AD2: statuValid | AE2: validateur | AF2: dateValid | AG2: commentVal
A3: 1 | B3: 1 | C3: 43987 | D3: Anse du Galon d'or | E3: Oui | F3: Comptage décadaire 2 | G3: Non | H3: Non-défini | J3: Accipiter nisus (Linnaeus, 1758) | K3: =IF(J3<>"",IF(VLOOKUP(J3,Taxons!A:C,2,FALSE)=0,"",VLOOKUP(J3,Taxons!A:C,2,FALSE)),"") -> Épervier d'Europe | L3: =IF(J3<>"",VLOOKUP(J3,Taxons!A:C,3,FALSE),"") -> 2895 | M3: 0.97638889 | N3: ROBIN Frédéric | S3: Présent | T3: 3 | U3: 2 | V3: 1 | Z3: Bonne précision | AA3: Inconnu | AB3: Non-défini | AD3: En attente de validation | AE3: ROBIN Frédéric | AF3: 43988
K4: =IF(J4<>"",IF(VLOOKUP(J4,Taxons!A:C,2,FALSE)=0,"",VLOOKUP(J4,Taxons!A:C,2,FALSE)),"") | L4: =IF(J4<>"",VLOOKUP(J4,Taxons!A:C,3,FALSE),"")
K5: =IF(J5<>"",IF(VLOOKUP(J5,Taxons!A:C,2,FALSE)=0,"",VLOOKUP(J5,Taxons!A:C,2,FALSE)),"") | L5: =IF(J5<>"",VLOOKUP(J5,Taxons!A:C,3,FALSE),"")
K6: =IF(J6<>"",IF(VLOOKUP(J6,Taxons!A:C,2,FALSE)=0,"",VLOOKUP(J6,Taxons!A:C,2,FALSE)),"") | L6: =IF(J6<>"",VLOOKUP(J6,Taxons!A:C,3,FALSE),"")
K7: =IF(J7<>"",IF(VLOOKUP(J7,Taxons!A:C,2,FALSE)=0,"",VLOOKUP(J7,Taxons!A:C,2,FALSE)),"") | L7: =IF(J7<>"",VLOOKUP(J7,Taxons!A:C,3,FALSE),"")
K8: =IF(J8<>"",IF(VLOOKUP(J8,Taxons!A:C,2,FALSE)=0,"",VLOOKUP(J8,Taxons!A:C,2,FALSE)),"") | L8: =IF(J8<>"",VLOOKUP(J8,Taxons!A:C,3,FALSE),"")
K9: =IF(J9<>"",IF(VLOOKUP(J9,Taxons!A:C,2,FALSE)=0,"",VLOOKUP(J9,Taxons!A:C,2,FALSE)),"") | L9: =IF(J9<>"",VLOOKUP(J9,Taxons!A:C,3,FALSE),"")
K10: =IF(J10<>"",IF(VLOOKUP(J10,Taxons!A:C,2,FALSE)=0,"",VLOOKUP(J10,Taxons!A:C,2,FALSE)),"") | L10: =IF(J10<>"",VLOOKUP(J10,Taxons!A:C,3,FALSE),"")
K11: =IF(J11<>"",IF(VLOOKUP(J11,Taxons!A:C,2,FALSE)=0,"",VLOOKUP(J11,Taxons!A:C,2,FALSE)),"") | L11: =IF(J11<>"",VLOOKUP(J11,Taxons!A:C,3,FALSE),"")
K12: =IF(J12<>"",IF(VLOOKUP(J12,Taxons!A:C,2,FALSE)=0,"",VLOOKUP(J12,Taxons!A:C,2,FALSE)),"") | L12: =IF(J12<>"",VLOOKUP(J12,Taxons!A:C,3,FALSE),"")
K13: =IF(J13<>"",IF(VLOOKUP(J13,Taxons!A:C,2,FALSE)=0,"",VLOOKUP(J13,Taxons!A:C,2,FALSE)),"") | L13: =IF(J13<>"",VLOOKUP(J13,Taxons!A:C,3,FALSE),"")
K14: =IF(J14<>"",IF(VLOOKUP(J14,Taxons!A:C,2,FALSE)=0,"",VLOOKUP(J14,Taxons!A:C,2,FALSE)),"") | L14: =IF(J14<>"",VLOOKUP(J14,Taxons!A:C,3,FALSE),"")
K15: =IF(J15<>"",IF(VLOOKUP(J15,Taxons!A:C,2,FALSE)=0,"",VLOOKUP(J15,Taxons!A:C,2,FALSE)),"") | L15: =IF(J15<>"",VLOOKUP(J15,Taxons!A:C,3,FALSE),"")
... K125: =IF(J125<>"",IF(VLOOKUP(J125,Taxons!A:C,2,FALSE)=0,"",VLOOKUP(J125,Taxons!A:C,2,FALSE)),"") | L125: =IF(J125<>"",VLOOKUP(J125,Taxons!A:C,3,FALSE),"")

Sheet IMPORTS
A1: id | B1: id_visit | C1: date_debut | D1: site | E1: comptage_mensuel | F1: decade | G1: derangement | H1: type_derangement | I1: nom_taxon | J1: nom_vernaculaire | K1: code_taxon | L1: heure | M1: observateu | N1: obs2 | O1: obs3 | P1: obs4 | Q1: obs5 | R1: statutObs | S1: effectif_total | T1: nb_ad_male | U1: nb_ad_femelle | V1: nb_ad | W1: nb_immat | X1: nb_juv | Y1: precision_comptage | Z1: comportement | AA1: code_atlas | AB1: commeObser | AC1: statuValid | AD1: validateur | AE1: dateValid | AF1: commentVal
A2: =IF('Comptage Décadaire'!A3<>"",VLOOKUP('Comptage Décadaire'!A3,'Comptage Décadaire'!A:A,1,FALSE),"") -> 1 | B2: =IF('Comptage Décadaire'!B3<>"",VLOOKUP('Comptage Décadaire'!B3,'Comptage Décadaire'!B:B,1,FALSE),"") -> 1 | C2: =IF('Comptage Décadaire'!C3<>"",VLOOKUP('Comptage Décadaire'!C3,'Comptage Décadaire'!C:C,1,FALSE),"") -> 43987 | D2: =IF('Comptage Décadaire'!D3<>"",VLOOKUP('Comptage Décadaire'!D3,Sites!$A:$B,2,FALSE),"") -> 1155 | E2: =IF('Comptage Décadaire'!E3<>"",VLOOKUP('Comptage Décadaire'!E3,'Comptage Décadaire'!E:E,1,FALSE),"") -> Oui | F2: =IF('Comptage Décadaire'!F3<>"",VLOOKUP('Comptage Décadaire'!F3,Nomenclature!$B$2:$C$4,2,FALSE),"") -> 663 | G2: =IF('Comptage Décadaire'!G3<>"",VLOOKUP('Comptage Décadaire'!G3,'Comptage Décadaire'!G:G,1,FALSE),"") -> Non | H2: =IF('Comptage Décadaire'!H3<>"",VLOOKUP('Comptage Décadaire'!H3,Nomenclature!$D$2:$E$7,2,FALSE),"") -> 691 | I2: =IF('Comptage Décadaire'!J3<>"",VLOOKUP('Comptage Décadaire'!J3,'Comptage Décadaire'!J:J,1,FALSE),"") -> Accipiter nisus (Linnaeus, 1758) | J2: =IF('Comptage Décadaire'!K3<>"",VLOOKUP('Comptage Décadaire'!K3,'Comptage Décadaire'!K:K,1,FALSE),"") -> Épervier d'Europe | K2: =IF('Comptage Décadaire'!L3<>"",VLOOKUP('Comptage Décadaire'!L3,'Comptage Décadaire'!L:L,1,FALSE),"") -> 2895 | L2: =IF('Comptage Décadaire'!M3<>"",VLOOKUP('Comptage Décadaire'!M3,'Comptage Décadaire'!M:M,1,FALSE),"") -> 0.97638889 | M2: =IF('Comptage Décadaire'!N3<>"",VLOOKUP('Comptage Décadaire'!N3,Utilisateurs!$D:$F,3,FALSE),"") -> 10 | N2: =IF('Comptage Décadaire'!O3<>"",VLOOKUP('Comptage Décadaire'!O3,Utilisateurs!$D:$F,3,FALSE),"") | O2: =IF('Comptage Décadaire'!P3<>"",VLOOKUP('Comptage Décadaire'!P3,Utilisateurs!$D:$F,3,FALSE),"") | P2: =IF('Comptage Décadaire'!Q3<>"",VLOOKUP('Comptage Décadaire'!Q3,Utilisateurs!$D:$F,3,FALSE),"") | Q2: =IF('Comptage Décadaire'!R3<>"",VLOOKUP('Comptage Décadaire'!R3,Utilisateurs!$D:$F,3,FALSE),"") | R2: =IF('Comptage Décadaire'!S3<>"",VLOOKUP('Comptage Décadaire'!S3,Nomenclature!$N:$O,2,FALSE),"") -> 84 | S2: =IF('Comptage Décadaire'!T3<>"",VLOOKUP('Comptage Décadaire'!T3,'Comptage Décadaire'!T:T,1,FALSE),"") -> 3 | T2: =IF('Comptage Décadaire'!U3<>"",VLOOKUP('Comptage Décadaire'!U3,'Comptage Décadaire'!U:U,1,FALSE),"") -> 2 | U2: =IF('Comptage Décadaire'!V3<>"",VLOOKUP('Comptage Décadaire'!V3,'Comptage Décadaire'!V:V,1,FALSE),"") -> 1 | V2: =IF('Comptage Décadaire'!W3<>"",VLOOKUP('Comptage Décadaire'!W3,'Comptage Décadaire'!W:W,1,FALSE),"") | W2: =IF('Comptage Décadaire'!X3<>"",VLOOKUP('Comptage Décadaire'!X3,'Comptage Décadaire'!X:X,1,FALSE),"") | X2: =IF('Comptage Décadaire'!Y3<>"",VLOOKUP('Comptage Décadaire'!Y3,'Comptage Décadaire'!Y:Y,1,FALSE),"") | Y2: =IF('Comptage Décadaire'!Z3<>"",VLOOKUP('Comptage Décadaire'!Z3,Nomenclature!$F$2:$G$7,2,FALSE),"") -> 639 | Z2: =IF('Comptage Décadaire'!AA3<>"",VLOOKUP('Comptage Décadaire'!AA3,Nomenclature!$H$2:$I$31,2,FALSE),"") -> 543 | AA2: =IF('Comptage Décadaire'!AB3<>"",VLOOKUP('Comptage Décadaire'!AB3,Nomenclature!$J$2:$K$21,2,FALSE),"") -> 664 | AB2: =IF('Comptage Décadaire'!AC3<>"",VLOOKUP('Comptage Décadaire'!AC3,'Comptage Décadaire'!AC:AC,1,FALSE),"") | AC2: =IF('Comptage Décadaire'!AD3<>"",VLOOKUP('Comptage Décadaire'!AD3,Nomenclature!$L$2:$M$8,2,FALSE),"") -> 457 | AD2: =IF('Comptage Décadaire'!AE3<>"",VLOOKUP('Comptage Décadaire'!AE3,Utilisateurs!$D$2:$F$81,3,FALSE),"") -> 10 | AE2: =IF('Comptage Décadaire'!AF3<>"",VLOOKUP('Comptage Décadaire'!AF3,'Comptage Décadaire'!AF:AF,1,FALSE),"") -> 43988 | AF2: =IF('Comptage Décadaire'!AG3<>"",VLOOKUP('Comptage Décadaire'!AG3,'Comptage Décadaire'!AG:AG,1,FALSE),"")
A3: =IF('Comptage Décadaire'!A4<>"",VLOOKUP('Comptage Décadaire'!A4,'Comptage Décadaire'!A:A,1,FALSE),"") | B3: =IF('Comptage Décadaire'!B4<>"",VLOOKUP('Comptage Décadaire'!B4,'Comptage Décadaire'!B:B,1,FALSE),"") | C3: =IF('Comptage Décadaire'!C4<>"",VLOOKUP('Comptage Décadaire'!C4,'Comptage Décadaire'!C:C,1,FALSE),"") | D3: =IF('Comptage Décadaire'!D4<>"",VLOOKUP('Comptage Décadaire'!D4,Sites!$A:$B,2,FALSE),"") | E3: =IF('Comptage Décadaire'!E4<>"",VLOOKUP('Comptage Décadaire'!E4,'Comptage Décadaire'!E:E,1,FALSE),"") | F3: =IF('Comptage Décadaire'!F4<>"",VLOOKUP('Comptage Décadaire'!F4,Nomenclature!$B$2:$C$4,2,FALSE),"") | G3: =IF('Comptage Décadaire'!G4<>"",VLOOKUP('Comptage Décadaire'!G4,'Comptage Décadaire'!G:G,1,FALSE),"") | H3: =IF('Comptage Décadaire'!H4<>"",VLOOKUP('Comptage Décadaire'!H4,Nomenclature!$D$2:$E$7,2,FALSE),"") | I3: =IF('Comptage Décadaire'!J4<>"",VLOOKUP('Comptage Décadaire'!J4,'Comptage Décadaire'!J:J,1,FALSE),"") | J3: =IF('Comptage Décadaire'!K4<>"",VLOOKUP('Comptage Décadaire'!K4,'Comptage Décadaire'!K:K,1,FALSE),"") | K3: =IF('Comptage Décadaire'!L4<>"",VLOOKUP('Comptage Décadaire'!L4,'Comptage Décadaire'!L:L,1,FALSE),"") | L3: =IF('Comptage Décadaire'!M4<>"",VLOOKUP('Comptage Décadaire'!M4,'Comptage Décadaire'!M:M,1,FALSE),"") | M3: =IF('Comptage Décadaire'!N4<>"",VLOOKUP('Comptage Décadaire'!N4,Utilisateurs!$D:$F,3,FALSE),"") | N3: =IF('Comptage Décadaire'!O4<>"",VLOOKUP('Comptage Décadaire'!O4,Utilisateurs!$D:$F,3,FALSE),"") | O3: =IF('Comptage Décadaire'!P4<>"",VLOOKUP('Comptage Décadaire'!P4,Utilisateurs!$D:$F,3,FALSE),"") | P3: =IF('Comptage Décadaire'!Q4<>"",VLOOKUP('Comptage Décadaire'!Q4,Utilisateurs!$D:$F,3,FALSE),"") | Q3: =IF('Comptage Décadaire'!R4<>"",VLOOKUP('Comptage Décadaire'!R4,Utilisateurs!$D:$F,3,FALSE),"") | R3: =IF('Comptage Décadaire'!S4<>"",VLOOKUP('Comptage Décadaire'!S4,Nomenclature!$N:$O,2,FALSE),"") | S3: =IF('Comptage Décadaire'!T4<>"",VLOOKUP('Comptage Décadaire'!T4,'Comptage Décadaire'!T:T,1,FALSE),"") | T3: =IF('Comptage Décadaire'!U4<>"",VLOOKUP('Comptage Décadaire'!U4,'Comptage Décadaire'!U:U,1,FALSE),"") | U3: =IF('Comptage Décadaire'!V4<>"",VLOOKUP('Comptage Décadaire'!V4,'Comptage Décadaire'!V:V,1,FALSE),"") | V3: =IF('Comptage Décadaire'!W4<>"",VLOOKUP('Comptage Décadaire'!W4,'Comptage Décadaire'!W:W,1,FALSE),"") | W3: =IF('Comptage Décadaire'!X4<>"",VLOOKUP('Comptage Décadaire'!X4,'Comptage Décadaire'!X:X,1,FALSE),"") | X3: =IF('Comptage Décadaire'!Y4<>"",VLOOKUP('Comptage Décadaire'!Y4,'Comptage Décadaire'!Y:Y,1,FALSE),"") | Y3: =IF('Comptage Décadaire'!Z4<>"",VLOOKUP('Comptage Décadaire'!Z4,Nomenclature!$F$2:$G$7,2,FALSE),"") | Z3: =IF('Comptage Décadaire'!AA4<>"",VLOOKUP('Comptage Décadaire'!AA4,Nomenclature!$H$2:$I$31,2,FALSE),"") | AA3: =IF('Comptage Décadaire'!AB4<>"",VLOOKUP('Comptage Décadaire'!AB4,Nomenclature!$J$2:$K$21,2,FALSE),"") | AB3: =IF('Comptage Décadaire'!AC4<>"",VLOOKUP('Comptage Décadaire'!AC4,'Comptage Décadaire'!AC:AC,1,FALSE),"") | AC3: =IF('Comptage Décadaire'!AD4<>"",VLOOKUP('Comptage Décadaire'!AD4,Nomenclature!$L$2:$M$8,2,FALSE),"") | AD3: =IF('Comptage Décadaire'!AE4<>"",VLOOKUP('Comptage Décadaire'!AE4,Utilisateurs!$D$2:$F$81,3,FALSE),"") | AE3: =IF('Comptage Décadaire'!AF4<>"",VLOOKUP('Comptage Décadaire'!AF4,'Comptage Décadaire'!AF:AF,1,FALSE),"") | AF3: =IF('Comptage Décadaire'!AG4<>"",VLOOKUP('Comptage Décadaire'!AG4,'Comptage Décadaire'!AG:AG,1,FALSE),"")
A4: =IF('Comptage Décadaire'!A5<>"",VLOOKUP('Comptage Décadaire'!A5,'Comptage Décadaire'!A:A,1,FALSE),"") | B4: =IF('Comptage Décadaire'!B5<>"",VLOOKUP('Comptage Décadaire'!B5,'Comptage Décadaire'!B:B,1,FALSE),"") | C4: =IF('Comptage Décadaire'!C5<>"",VLOOKUP('Comptage Décadaire'!C5,'Comptage Décadaire'!C:C,1,FALSE),"") | D4: =IF('Comptage Décadaire'!D5<>"",VLOOKUP('Comptage Décadaire'!D5,Sites!$A:$B,2,FALSE),"") | E4: =IF('Comptage Décadaire'!E5<>"",VLOOKUP('Comptage Décadaire'!E5,'Comptage Décadaire'!E:E,1,FALSE),"") | F4: =IF('Comptage Décadaire'!F5<>"",VLOOKUP('Comptage Décadaire'!F5,Nomenclature!$B$2:$C$4,2,FALSE),"") | G4: =IF('Comptage Décadaire'!G5<>"",VLOOKUP('Comptage Décadaire'!G5,'Comptage Décadaire'!G:G,1,FALSE),"") | H4: =IF('Comptage Décadaire'!H5<>"",VLOOKUP('Comptage Décadaire'!H5,Nomenclature!$D$2:$E$7,2,FALSE),"") | I4: =IF('Comptage Décadaire'!J5<>"",VLOOKUP('Comptage Décadaire'!J5,'Comptage Décadaire'!J:J,1,FALSE),"") | J4: =IF('Comptage Décadaire'!K5<>"",VLOOKUP('Comptage Décadaire'!K5,'Comptage Décadaire'!K:K,1,FALSE),"") | K4: =IF('Comptage Décadaire'!L5<>"",VLOOKUP('Comptage Décadaire'!L5,'Comptage Décadaire'!L:L,1,FALSE),"") | L4: =IF('Comptage Décadaire'!M5<>"",VLOOKUP('Comptage Décadaire'!M5,'Comptage Décadaire'!M:M,1,FALSE),"") | M4: =IF('Comptage Décadaire'!N5<>"",VLOOKUP('Comptage Décadaire'!N5,Utilisateurs!$D:$F,3,FALSE),"") | N4: =IF('Comptage Décadaire'!O5<>"",VLOOKUP('Comptage Décadaire'!O5,Utilisateurs!$D:$F,3,FALSE),"") | O4: =IF('Comptage Décadaire'!P5<>"",VLOOKUP('Comptage Décadaire'!P5,Utilisateurs!$D:$F,3,FALSE),"") | P4: =IF('Comptage Décadaire'!Q5<>"",VLOOKUP('Comptage Décadaire'!Q5,Utilisateurs!$D:$F,3,FALSE),"") | Q4: =IF('Comptage Décadaire'!R5<>"",VLOOKUP('Comptage Décadaire'!R5,Utilisateurs!$D:$F,3,FALSE),"") | R4: =IF('Comptage Décadaire'!S5<>"",VLOOKUP('Comptage Décadaire'!S5,Nomenclature!$N:$O,2,FALSE),"") | S4: =IF('Comptage Décadaire'!T5<>"",VLOOKUP('Comptage Décadaire'!T5,'Comptage Décadaire'!T:T,1,FALSE),"") | T4: =IF('Comptage Décadaire'!U5<>"",VLOOKUP('Comptage Décadaire'!U5,'Comptage Décadaire'!U:U,1,FALSE),"") | U4: =IF('Comptage Décadaire'!V5<>"",VLOOKUP('Comptage Décadaire'!V5,'Comptage Décadaire'!V:V,1,FALSE),"") | V4: =IF('Comptage Décadaire'!W5<>"",VLOOKUP('Comptage Décadaire'!W5,'Comptage Décadaire'!W:W,1,FALSE),"") | W4: =IF('Comptage Décadaire'!X5<>"",VLOOKUP('Comptage Décadaire'!X5,'Comptage Décadaire'!X:X,1,FALSE),"") | X4: =IF('Comptage Décadaire'!Y5<>"",VLOOKUP('Comptage Décadaire'!Y5,'Comptage Décadaire'!Y:Y,1,FALSE),"") | Y4: =IF('Comptage Décadaire'!Z5<>"",VLOOKUP('Comptage Décadaire'!Z5,Nomenclature!$F$2:$G$7,2,FALSE),"") | Z4: =IF('Comptage Décadaire'!AA5<>"",VLOOKUP('Comptage Décadaire'!AA5,Nomenclature!$H$2:$I$31,2,FALSE),"") | AA4: =IF('Comptage Décadaire'!AB5<>"",VLOOKUP('Comptage Décadaire'!AB5,Nomenclature!$J$2:$K$21,2,FALSE),"") | AB4: =IF('Comptage Décadaire'!AC5<>"",VLOOKUP('Comptage Décadaire'!AC5,'Comptage Décadaire'!AC:AC,1,FALSE),"") | AC4: =IF('Comptage Décadaire'!AD5<>"",VLOOKUP('Comptage Décadaire'!AD5,Nomenclature!$L$2:$M$8,2,FALSE),"") | AD4: =IF('Comptage Décadaire'!AE5<>"",VLOOKUP('Comptage Décadaire'!AE5,Utilisateurs!$D$2:$F$81,3,FALSE),"") | AE4: =IF('Comptage Décadaire'!AF5<>"",VLOOKUP('Comptage Décadaire'!AF5,'Comptage Décadaire'!AF:AF,1,FALSE),"") | AF4: =IF('Comptage Décadaire'!AG5<>"",VLOOKUP('Comptage Décadaire'!AG5,'Comptage Décadaire'!AG:AG,1,FALSE),"")
A5: =IF('Comptage Décadaire'!A6<>"",VLOOKUP('Comptage Décadaire'!A6,'Comptage Décadaire'!A:A,1,FALSE),"") | B5: =IF('Comptage Décadaire'!B6<>"",VLOOKUP('Comptage Décadaire'!B6,'Comptage Décadaire'!B:B,1,FALSE),"") | C5: =IF('Comptage Décadaire'!C6<>"",VLOOKUP('Comptage Décadaire'!C6,'Comptage Décadaire'!C:C,1,FALSE),"") | D5: =IF('Comptage Décadaire'!D6<>"",VLOOKUP('Comptage Décadaire'!D6,Sites!$A:$B,2,FALSE),"") | E5: =IF('Comptage Décadaire'!E6<>"",VLOOKUP('Comptage Décadaire'!E6,'Comptage Décadaire'!E:E,1,FALSE),"") | F5: =IF('Comptage Décadaire'!F6<>"",VLOOKUP('Comptage Décadaire'!F6,Nomenclature!$B$2:$C$4,2,FALSE),"") | G5: =IF('Comptage Décadaire'!G6<>"",VLOOKUP('Comptage Décadaire'!G6,'Comptage Décadaire'!G:G,1,FALSE),"") | H5: =IF('Comptage Décadaire'!H6<>"",VLOOKUP('Comptage Décadaire'!H6,Nomenclature!$D$2:$E$7,2,FALSE),"") | I5: =IF('Comptage Décadaire'!J6<>"",VLOOKUP('Comptage Décadaire'!J6,'Comptage Décadaire'!J:J,1,FALSE),"") | J5: =IF('Comptage Décadaire'!K6<>"",VLOOKUP('Comptage Décadaire'!K6,'Comptage Décadaire'!K:K,1,FALSE),"") | K5: =IF('Comptage Décadaire'!L6<>"",VLOOKUP('Comptage Décadaire'!L6,'Comptage Décadaire'!L:L,1,FALSE),"") | L5: =IF('Comptage Décadaire'!M6<>"",VLOOKUP('Comptage Décadaire'!M6,'Comptage Décadaire'!M:M,1,FALSE),"") | M5: =IF('Comptage Décadaire'!N6<>"",VLOOKUP('Comptage Décadaire'!N6,Utilisateurs!$D:$F,3,FALSE),"") | N5: =IF('Comptage Décadaire'!O6<>"",VLOOKUP('Comptage Décadaire'!O6,Utilisateurs!$D:$F,3,FALSE),"") | O5: =IF('Comptage Décadaire'!P6<>"",VLOOKUP('Comptage Décadaire'!P6,Utilisateurs!$D:$F,3,FALSE),"") | P5: =IF('Comptage Décadaire'!Q6<>"",VLOOKUP('Comptage Décadaire'!Q6,Utilisateurs!$D:$F,3,FALSE),"") | Q5: =IF('Comptage Décadaire'!R6<>"",VLOOKUP('Comptage Décadaire'!R6,Utilisateurs!$D:$F,3,FALSE),"") | R5: =IF('Comptage Décadaire'!S6<>"",VLOOKUP('Comptage Décadaire'!S6,Nomenclature!$N:$O,2,FALSE),"") | S5: =IF('Comptage Décadaire'!T6<>"",VLOOKUP('Comptage Décadaire'!T6,'Comptage Décadaire'!T:T,1,FALSE),"") | T5: =IF('Comptage Décadaire'!U6<>"",VLOOKUP('Comptage Décadaire'!U6,'Comptage Décadaire'!U:U,1,FALSE),"") | U5: =IF('Comptage Décadaire'!V6<>"",VLOOKUP('Comptage Décadaire'!V6,'Comptage Décadaire'!V:V,1,FALSE),"") | V5: =IF('Comptage Décadaire'!W6<>"",VLOOKUP('Comptage Décadaire'!W6,'Comptage Décadaire'!W:W,1,FALSE),"") | W5: =IF('Comptage Décadaire'!X6<>"",VLOOKUP('Comptage Décadaire'!X6,'Comptage Décadaire'!X:X,1,FALSE),"") | X5: =IF('Comptage Décadaire'!Y6<>"",VLOOKUP('Comptage Décadaire'!Y6,'Comptage Décadaire'!Y:Y,1,FALSE),"") | Y5: =IF('Comptage Décadaire'!Z6<>"",VLOOKUP('Comptage Décadaire'!Z6,Nomenclature!$F$2:$G$7,2,FALSE),"") | Z5: =IF('Comptage Décadaire'!AA6<>"",VLOOKUP('Comptage Décadaire'!AA6,Nomenclature!$H$2:$I$31,2,FALSE),"") | AA5: =IF('Comptage Décadaire'!AB6<>"",VLOOKUP('Comptage Décadaire'!AB6,Nomenclature!$J$2:$K$21,2,FALSE),"") | AB5: =IF('Comptage Décadaire'!AC6<>"",VLOOKUP('Comptage Décadaire'!AC6,'Comptage Décadaire'!AC:AC,1,FALSE),"") | AC5: =IF('Comptage Décadaire'!AD6<>"",VLOOKUP('Comptage Décadaire'!AD6,Nomenclature!$L$2:$M$8,2,FALSE),"") | AD5: =IF('Comptage Décadaire'!AE6<>"",VLOOKUP('Comptage Décadaire'!AE6,Utilisateurs!$D$2:$F$81,3,FALSE),"") | AE5: =IF('Comptage Décadaire'!AF6<>"",VLOOKUP('Comptage Décadaire'!AF6,'Comptage Décadaire'!AF:AF,1,FALSE),"") | AF5: =IF('Comptage Décadaire'!AG6<>"",VLOOKUP('Comptage Décadaire'!AG6,'Comptage Décadaire'!AG:AG,1,FALSE),"")
A6: =IF('Comptage Décadaire'!A7<>"",VLOOKUP('Comptage Décadaire'!A7,'Comptage Décadaire'!A:A,1,FALSE),"") | B6: =IF('Comptage Décadaire'!B7<>"",VLOOKUP('Comptage Décadaire'!B7,'Comptage Décadaire'!B:B,1,FALSE),"") | C6: =IF('Comptage Décadaire'!C7<>"",VLOOKUP('Comptage Décadaire'!C7,'Comptage Décadaire'!C:C,1,FALSE),"") | D6: =IF('Comptage Décadaire'!D7<>"",VLOOKUP('Comptage Décadaire'!D7,Sites!$A:$B,2,FALSE),"") | E6: =IF('Comptage Décadaire'!E7<>"",VLOOKUP('Comptage Décadaire'!E7,'Comptage Décadaire'!E:E,1,FALSE),"") | F6: =IF('Comptage Décadaire'!F7<>"",VLOOKUP('Comptage Décadaire'!F7,Nomenclature!$B$2:$C$4,2,FALSE),"") | G6: =IF('Comptage Décadaire'!G7<>"",VLOOKUP('Comptage Décadaire'!G7,'Comptage Décadaire'!G:G,1,FALSE),"") | H6: =IF('Comptage Décadaire'!H7<>"",VLOOKUP('Comptage Décadaire'!H7,Nomenclature!$D$2:$E$7,2,FALSE),"") | I6: =IF('Comptage Décadaire'!J7<>"",VLOOKUP('Comptage Décadaire'!J7,'Comptage Décadaire'!J:J,1,FALSE),"") | J6: =IF('Comptage Décadaire'!K7<>"",VLOOKUP('Comptage Décadaire'!K7,'Comptage Décadaire'!K:K,1,FALSE),"") | K6: =IF('Comptage Décadaire'!L7<>"",VLOOKUP('Comptage Décadaire'!L7,'Comptage Décadaire'!L:L,1,FALSE),"") | L6: =IF('Comptage Décadaire'!M7<>"",VLOOKUP('Comptage Décadaire'!M7,'Comptage Décadaire'!M:M,1,FALSE),"") | M6: =IF('Comptage Décadaire'!N7<>"",VLOOKUP('Comptage Décadaire'!N7,Utilisateurs!$D:$F,3,FALSE),"") | N6: =IF('Comptage Décadaire'!O7<>"",VLOOKUP('Comptage Décadaire'!O7,Utilisateurs!$D:$F,3,FALSE),"") | O6: =IF('Comptage Décadaire'!P7<>"",VLOOKUP('Comptage Décadaire'!P7,Utilisateurs!$D:$F,3,FALSE),"") | P6: =IF('Comptage Décadaire'!Q7<>"",VLOOKUP('Comptage Décadaire'!Q7,Utilisateurs!$D:$F,3,FALSE),"") | Q6: =IF('Comptage Décadaire'!R7<>"",VLOOKUP('Comptage Décadaire'!R7,Utilisateurs!$D:$F,3,FALSE),"") | R6: =IF('Comptage Décadaire'!S7<>"",VLOOKUP('Comptage Décadaire'!S7,Nomenclature!$N:$O,2,FALSE),"") | S6: =IF('Comptage Décadaire'!T7<>"",VLOOKUP('Comptage Décadaire'!T7,'Comptage Décadaire'!T:T,1,FALSE),"") | T6: =IF('Comptage Décadaire'!U7<>"",VLOOKUP('Comptage Décadaire'!U7,'Comptage Décadaire'!U:U,1,FALSE),"") | U6: =IF('Comptage Décadaire'!V7<>"",VLOOKUP('Comptage Décadaire'!V7,'Comptage Décadaire'!V:V,1,FALSE),"") | V6: =IF('Comptage Décadaire'!W7<>"",VLOOKUP('Comptage Décadaire'!W7,'Comptage Décadaire'!W:W,1,FALSE),"") | W6: =IF('Comptage Décadaire'!X7<>"",VLOOKUP('Comptage Décadaire'!X7,'Comptage Décadaire'!X:X,1,FALSE),"") | X6: =IF('Comptage Décadaire'!Y7<>"",VLOOKUP('Comptage Décadaire'!Y7,'Comptage Décadaire'!Y:Y,1,FALSE),"") | Y6: =IF('Comptage Décadaire'!Z7<>"",VLOOKUP('Comptage Décadaire'!Z7,Nomenclature!$F$2:$G$7,2,FALSE),"") | Z6: =IF('Comptage Décadaire'!AA7<>"",VLOOKUP('Comptage Décadaire'!AA7,Nomenclature!$H$2:$I$31,2,FALSE),"") | AA6: =IF('Comptage Décadaire'!AB7<>"",VLOOKUP('Comptage Décadaire'!AB7,Nomenclature!$J$2:$K$21,2,FALSE),"") | AB6: =IF('Comptage Décadaire'!AC7<>"",VLOOKUP('Comptage Décadaire'!AC7,'Comptage Décadaire'!AC:AC,1,FALSE),"") | AC6: =IF('Comptage Décadaire'!AD7<>"",VLOOKUP('Comptage Décadaire'!AD7,Nomenclature!$L$2:$M$8,2,FALSE),"") | AD6: =IF('Comptage Décadaire'!AE7<>"",VLOOKUP('Comptage Décadaire'!AE7,Utilisateurs!$D$2:$F$81,3,FALSE),"") | AE6: =IF('Comptage Décadaire'!AF7<>"",VLOOKUP('Comptage Décadaire'!AF7,'Comptage Décadaire'!AF:AF,1,FALSE),"") | AF6: =IF('Comptage Décadaire'!AG7<>"",VLOOKUP('Comptage Décadaire'!AG7,'Comptage Décadaire'!AG:AG,1,FALSE),"")
A7: =IF('Comptage Décadaire'!A8<>"",VLOOKUP('Comptage Décadaire'!A8,'Comptage Décadaire'!A:A,1,FALSE),"") | B7: =IF('Comptage Décadaire'!B8<>"",VLOOKUP('Comptage Décadaire'!B8,'Comptage Décadaire'!B:B,1,FALSE),"") | C7: =IF('Comptage Décadaire'!C8<>"",VLOOKUP('Comptage Décadaire'!C8,'Comptage Décadaire'!C:C,1,FALSE),"") | D7: =IF('Comptage Décadaire'!D8<>"",VLOOKUP('Comptage Décadaire'!D8,Sites!$A:$B,2,FALSE),"") | E7: =IF('Comptage Décadaire'!E8<>"",VLOOKUP('Comptage Décadaire'!E8,'Comptage Décadaire'!E:E,1,FALSE),"") | F7: =IF('Comptage Décadaire'!F8<>"",VLOOKUP('Comptage Décadaire'!F8,Nomenclature!$B$2:$C$4,2,FALSE),"") | G7: =IF('Comptage Décadaire'!G8<>"",VLOOKUP('Comptage Décadaire'!G8,'Comptage Décadaire'!G:G,1,FALSE),"") | H7: =IF('Comptage Décadaire'!H8<>"",VLOOKUP('Comptage Décadaire'!H8,Nomenclature!$D$2:$E$7,2,FALSE),"") | I7: =IF('Comptage Décadaire'!J8<>"",VLOOKUP('Comptage Décadaire'!J8,'Comptage Décadaire'!J:J,1,FALSE),"") | J7: =IF('Comptage Décadaire'!K8<>"",VLOOKUP('Comptage Décadaire'!K8,'Comptage Décadaire'!K:K,1,FALSE),"") | K7: =IF('Comptage Décadaire'!L8<>"",VLOOKUP('Comptage Décadaire'!L8,'Comptage Décadaire'!L:L,1,FALSE),"") | L7: =IF('Comptage Décadaire'!M8<>"",VLOOKUP('Comptage Décadaire'!M8,'Comptage Décadaire'!M:M,1,FALSE),"") | M7: =IF('Comptage Décadaire'!N8<>"",VLOOKUP('Comptage Décadaire'!N8,Utilisateurs!$D:$F,3,FALSE),"") | N7: =IF('Comptage Décadaire'!O8<>"",VLOOKUP('Comptage Décadaire'!O8,Utilisateurs!$D:$F,3,FALSE),"") | O7: =IF('Comptage Décadaire'!P8<>"",VLOOKUP('Comptage Décadaire'!P8,Utilisateurs!$D:$F,3,FALSE),"") | P7: =IF('Comptage Décadaire'!Q8<>"",VLOOKUP('Comptage Décadaire'!Q8,Utilisateurs!$D:$F,3,FALSE),"") | Q7: =IF('Comptage Décadaire'!R8<>"",VLOOKUP('Comptage Décadaire'!R8,Utilisateurs!$D:$F,3,FALSE),"") | R7: =IF('Comptage Décadaire'!S8<>"",VLOOKUP('Comptage Décadaire'!S8,Nomenclature!$N:$O,2,FALSE),"") | S7: =IF('Comptage Décadaire'!T8<>"",VLOOKUP('Comptage Décadaire'!T8,'Comptage Décadaire'!T:T,1,FALSE),"") | T7: =IF('Comptage Décadaire'!U8<>"",VLOOKUP('Comptage Décadaire'!U8,'Comptage Décadaire'!U:U,1,FALSE),"") | U7: =IF('Comptage Décadaire'!V8<>"",VLOOKUP('Comptage Décadaire'!V8,'Comptage Décadaire'!V:V,1,FALSE),"") | V7: =IF('Comptage Décadaire'!W8<>"",VLOOKUP('Comptage Décadaire'!W8,'Comptage Décadaire'!W:W,1,FALSE),"") | W7: =IF('Comptage Décadaire'!X8<>"",VLOOKUP('Comptage Décadaire'!X8,'Comptage Décadaire'!X:X,1,FALSE),"") | X7: =IF('Comptage Décadaire'!Y8<>"",VLOOKUP('Comptage Décadaire'!Y8,'Comptage Décadaire'!Y:Y,1,FALSE),"") | Y7: =IF('Comptage Décadaire'!Z8<>"",VLOOKUP('Comptage Décadaire'!Z8,Nomenclature!$F$2:$G$7,2,FALSE),"") | Z7: =IF('Comptage Décadaire'!AA8<>"",VLOOKUP('Comptage Décadaire'!AA8,Nomenclature!$H$2:$I$31,2,FALSE),"") | AA7: =IF('Comptage Décadaire'!AB8<>"",VLOOKUP('Comptage Décadaire'!AB8,Nomenclature!$J$2:$K$21,2,FALSE),"") | AB7: =IF('Comptage Décadaire'!AC8<>"",VLOOKUP('Comptage Décadaire'!AC8,'Comptage Décadaire'!AC:AC,1,FALSE),"") | AC7: =IF('Comptage Décadaire'!AD8<>"",VLOOKUP('Comptage Décadaire'!AD8,Nomenclature!$L$2:$M$8,2,FALSE),"") | AD7: =IF('Comptage Décadaire'!AE8<>"",VLOOKUP('Comptage Décadaire'!AE8,Utilisateurs!$D$2:$F$81,3,FALSE),"") | AE7: =IF('Comptage Décadaire'!AF8<>"",VLOOKUP('Comptage Décadaire'!AF8,'Comptage Décadaire'!AF:AF,1,FALSE),"") | AF7: =IF('Comptage Décadaire'!AG8<>"",VLOOKUP('Comptage Décadaire'!AG8,'Comptage Décadaire'!AG:AG,1,FALSE),"")
A8: =IF('Comptage Décadaire'!A9<>"",VLOOKUP('Comptage Décadaire'!A9,'Comptage Décadaire'!A:A,1,FALSE),"") | B8: =IF('Comptage Décadaire'!B9<>"",VLOOKUP('Comptage Décadaire'!B9,'Comptage Décadaire'!B:B,1,FALSE),"") | C8: =IF('Comptage Décadaire'!C9<>"",VLOOKUP('Comptage Décadaire'!C9,'Comptage Décadaire'!C:C,1,FALSE),"") | D8: =IF('Comptage Décadaire'!D9<>"",VLOOKUP('Comptage Décadaire'!D9,Sites!$A:$B,2,FALSE),"") | E8: =IF('Comptage Décadaire'!E9<>"",VLOOKUP('Comptage Décadaire'!E9,'Comptage Décadaire'!E:E,1,FALSE),"") | F8: =IF('Comptage Décadaire'!F9<>"",VLOOKUP('Comptage Décadaire'!F9,Nomenclature!$B$2:$C$4,2,FALSE),"") | G8: =IF('Comptage Décadaire'!G9<>"",VLOOKUP('Comptage Décadaire'!G9,'Comptage Décadaire'!G:G,1,FALSE),"") | H8: =IF('Comptage Décadaire'!H9<>"",VLOOKUP('Comptage Décadaire'!H9,Nomenclature!$D$2:$E$7,2,FALSE),"") | I8: =IF('Comptage Décadaire'!J9<>"",VLOOKUP('Comptage Décadaire'!J9,'Comptage Décadaire'!J:J,1,FALSE),"") | J8: =IF('Comptage Décadaire'!K9<>"",VLOOKUP('Comptage Décadaire'!K9,'Comptage Décadaire'!K:K,1,FALSE),"") | K8: =IF('Comptage Décadaire'!L9<>"",VLOOKUP('Comptage Décadaire'!L9,'Comptage Décadaire'!L:L,1,FALSE),"") | L8: =IF('Comptage Décadaire'!M9<>"",VLOOKUP('Comptage Décadaire'!M9,'Comptage Décadaire'!M:M,1,FALSE),"") | M8: =IF('Comptage Décadaire'!N9<>"",VLOOKUP('Comptage Décadaire'!N9,Utilisateurs!$D:$F,3,FALSE),"") | N8: =IF('Comptage Décadaire'!O9<>"",VLOOKUP('Comptage Décadaire'!O9,Utilisateurs!$D:$F,3,FALSE),"") | O8: =IF('Comptage Décadaire'!P9<>"",VLOOKUP('Comptage Décadaire'!P9,Utilisateurs!$D:$F,3,FALSE),"") | P8: =IF('Comptage Décadaire'!Q9<>"",VLOOKUP('Comptage Décadaire'!Q9,Utilisateurs!$D:$F,3,FALSE),"") | Q8: =IF('Comptage Décadaire'!R9<>"",VLOOKUP('Comptage Décadaire'!R9,Utilisateurs!$D:$F,3,FALSE),"") | R8: =IF('Comptage Décadaire'!S9<>"",VLOOKUP('Comptage Décadaire'!S9,Nomenclature!$N:$O,2,FALSE),"") | S8: =IF('Comptage Décadaire'!T9<>"",VLOOKUP('Comptage Décadaire'!T9,'Comptage Décadaire'!T:T,1,FALSE),"") | T8: =IF('Comptage Décadaire'!U9<>"",VLOOKUP('Comptage Décadaire'!U9,'Comptage Décadaire'!U:U,1,FALSE),"") | U8: =IF('Comptage Décadaire'!V9<>"",VLOOKUP('Comptage Décadaire'!V9,'Comptage Décadaire'!V:V,1,FALSE),"") | V8: =IF('Comptage Décadaire'!W9<>"",VLOOKUP('Comptage Décadaire'!W9,'Comptage Décadaire'!W:W,1,FALSE),"") | W8: =IF('Comptage Décadaire'!X9<>"",VLOOKUP('Comptage Décadaire'!X9,'Comptage Décadaire'!X:X,1,FALSE),"") | X8: =IF('Comptage Décadaire'!Y9<>"",VLOOKUP('Comptage Décadaire'!Y9,'Comptage Décadaire'!Y:Y,1,FALSE),"") | Y8: =IF('Comptage Décadaire'!Z9<>"",VLOOKUP('Comptage Décadaire'!Z9,Nomenclature!$F$2:$G$7,2,FALSE),"") | Z8: =IF('Comptage Décadaire'!AA9<>"",VLOOKUP('Comptage Décadaire'!AA9,Nomenclature!$H$2:$I$31,2,FALSE),"") | AA8: =IF('Comptage Décadaire'!AB9<>"",VLOOKUP('Comptage Décadaire'!AB9,Nomenclature!$J$2:$K$21,2,FALSE),"") | AB8: =IF('Comptage Décadaire'!AC9<>"",VLOOKUP('Comptage Décadaire'!AC9,'Comptage Décadaire'!AC:AC,1,FALSE),"") | AC8: =IF('Comptage Décadaire'!AD9<>"",VLOOKUP('Comptage Décadaire'!AD9,Nomenclature!$L$2:$M$8,2,FALSE),"") | AD8: =IF('Comptage Décadaire'!AE9<>"",VLOOKUP('Comptage Décadaire'!AE9,Utilisateurs!$D$2:$F$81,3,FALSE),"") | AE8: =IF('Comptage Décadaire'!AF9<>"",VLOOKUP('Comptage Décadaire'!AF9,'Comptage Décadaire'!AF:AF,1,FALSE),"") | AF8: =IF('Comptage Décadaire'!AG9<>"",VLOOKUP('Comptage Décadaire'!AG9,'Comptage Décadaire'!AG:AG,1,FALSE),"")
A9: =IF('Comptage Décadaire'!A10<>"",VLOOKUP('Comptage Décadaire'!A10,'Comptage Décadaire'!A:A,1,FALSE),"") | B9: =IF('Comptage Décadaire'!B10<>"",VLOOKUP('Comptage Décadaire'!B10,'Comptage Décadaire'!B:B,1,FALSE),"") | C9: =IF('Comptage Décadaire'!C10<>"",VLOOKUP('Comptage Décadaire'!C10,'Comptage Décadaire'!C:C,1,FALSE),"") | D9: =IF('Comptage Décadaire'!D10<>"",VLOOKUP('Comptage Décadaire'!D10,Sites!$A:$B,2,FALSE),"") | E9: =IF('Comptage Décadaire'!E10<>"",VLOOKUP('Comptage Décadaire'!E10,'Comptage Décadaire'!E:E,1,FALSE),"") | F9: =IF('Comptage Décadaire'!F10<>"",VLOOKUP('Comptage Décadaire'!F10,Nomenclature!$B$2:$C$4,2,FALSE),"") | G9: =IF('Comptage Décadaire'!G10<>"",VLOOKUP('Comptage Décadaire'!G10,'Comptage Décadaire'!G:G,1,FALSE),"") | H9: =IF('Comptage Décadaire'!H10<>"",VLOOKUP('Comptage Décadaire'!H10,Nomenclature!$D$2:$E$7,2,FALSE),"") | I9: =IF('Comptage Décadaire'!J10<>"",VLOOKUP('Comptage Décadaire'!J10,'Comptage Décadaire'!J:J,1,FALSE),"") | J9: =IF('Comptage Décadaire'!K10<>"",VLOOKUP('Comptage Décadaire'!K10,'Comptage Décadaire'!K:K,1,FALSE),"") | K9: =IF('Comptage Décadaire'!L10<>"",VLOOKUP('Comptage Décadaire'!L10,'Comptage Décadaire'!L:L,1,FALSE),"") | L9: =IF('Comptage Décadaire'!M10<>"",VLOOKUP('Comptage Décadaire'!M10,'Comptage Décadaire'!M:M,1,FALSE),"") | M9: =IF('Comptage Décadaire'!N10<>"",VLOOKUP('Comptage Décadaire'!N10,Utilisateurs!$D:$F,3,FALSE),"") | N9: =IF('Comptage Décadaire'!O10<>"",VLOOKUP('Comptage Décadaire'!O10,Utilisateurs!$D:$F,3,FALSE),"") | O9: =IF('Comptage Décadaire'!P10<>"",VLOOKUP('Comptage Décadaire'!P10,Utilisateurs!$D:$F,3,FALSE),"") | P9: =IF('Comptage Décadaire'!Q10<>"",VLOOKUP('Comptage Décadaire'!Q10,Utilisateurs!$D:$F,3,FALSE),"") | Q9: =IF('Comptage Décadaire'!R10<>"",VLOOKUP('Comptage Décadaire'!R10,Utilisateurs!$D:$F,3,FALSE),"") | R9: =IF('Comptage Décadaire'!S10<>"",VLOOKUP('Comptage Décadaire'!S10,Nomenclature!$N:$O,2,FALSE),"") | S9: =IF('Comptage Décadaire'!T10<>"",VLOOKUP('Comptage Décadaire'!T10,'Comptage Décadaire'!T:T,1,FALSE),"") | T9: =IF('Comptage Décadaire'!U10<>"",VLOOKUP('Comptage Décadaire'!U10,'Comptage Décadaire'!U:U,1,FALSE),"") | U9: =IF('Comptage Décadaire'!V10<>"",VLOOKUP('Comptage Décadaire'!V10,'Comptage Décadaire'!V:V,1,FALSE),"") | V9: =IF('Comptage Décadaire'!W10<>"",VLOOKUP('Comptage Décadaire'!W10,'Comptage Décadaire'!W:W,1,FALSE),"") | W9: =IF('Comptage Décadaire'!X10<>"",VLOOKUP('Comptage Décadaire'!X10,'Comptage Décadaire'!X:X,1,FALSE),"") | X9: =IF('Comptage Décadaire'!Y10<>"",VLOOKUP('Comptage Décadaire'!Y10,'Comptage Décadaire'!Y:Y,1,FALSE),"") | Y9: =IF('Comptage Décadaire'!Z10<>"",VLOOKUP('Comptage Décadaire'!Z10,Nomenclature!$F$2:$G$7,2,FALSE),"") | Z9: =IF('Comptage Décadaire'!AA10<>"",VLOOKUP('Comptage Décadaire'!AA10,Nomenclature!$H$2:$I$31,2,FALSE),"") | AA9: =IF('Comptage Décadaire'!AB10<>"",VLOOKUP('Comptage Décadaire'!AB10,Nomenclature!$J$2:$K$21,2,FALSE),"") | AB9: =IF('Comptage Décadaire'!AC10<>"",VLOOKUP('Comptage Décadaire'!AC10,'Comptage Décadaire'!AC:AC,1,FALSE),"") | AC9: =IF('Comptage Décadaire'!AD10<>"",VLOOKUP('Comptage Décadaire'!AD10,Nomenclature!$L$2:$M$8,2,FALSE),"") | AD9: =IF('Comptage Décadaire'!AE10<>"",VLOOKUP('Comptage Décadaire'!AE10,Utilisateurs!$D$2:$F$81,3,FALSE),"") | AE9: =IF('Comptage Décadaire'!AF10<>"",VLOOKUP('Comptage Décadaire'!AF10,'Comptage Décadaire'!AF:AF,1,FALSE),"") | AF9: =IF('Comptage Décadaire'!AG10<>"",VLOOKUP('Comptage Décadaire'!AG10,'Comptage Décadaire'!AG:AG,1,FALSE),"")
A10: =IF('Comptage Décadaire'!A11<>"",VLOOKUP('Comptage Décadaire'!A11,'Comptage Décadaire'!A:A,1,FALSE),"") | B10: =IF('Comptage Décadaire'!B11<>"",VLOOKUP('Comptage Décadaire'!B11,'Comptage Décadaire'!B:B,1,FALSE),"") | C10: =IF('Comptage Décadaire'!C11<>"",VLOOKUP('Comptage Décadaire'!C11,'Comptage Décadaire'!C:C,1,FALSE),"") | D10: =IF('Comptage Décadaire'!D11<>"",VLOOKUP('Comptage Décadaire'!D11,Sites!$A:$B,2,FALSE),"") | E10: =IF('Comptage Décadaire'!E11<>"",VLOOKUP('Comptage Décadaire'!E11,'Comptage Décadaire'!E:E,1,FALSE),"") | F10: =IF('Comptage Décadaire'!F11<>"",VLOOKUP('Comptage Décadaire'!F11,Nomenclature!$B$2:$C$4,2,FALSE),"") | G10: =IF('Comptage Décadaire'!G11<>"",VLOOKUP('Comptage Décadaire'!G11,'Comptage Décadaire'!G:G,1,FALSE),"") | H10: =IF('Comptage Décadaire'!H11<>"",VLOOKUP('Comptage Décadaire'!H11,Nomenclature!$D$2:$E$7,2,FALSE),"") | I10: =IF('Comptage Décadaire'!J11<>"",VLOOKUP('Comptage Décadaire'!J11,'Comptage Décadaire'!J:J,1,FALSE),"") | J10: =IF('Comptage Décadaire'!K11<>"",VLOOKUP('Comptage Décadaire'!K11,'Comptage Décadaire'!K:K,1,FALSE),"") | K10: =IF('Comptage Décadaire'!L11<>"",VLOOKUP('Comptage Décadaire'!L11,'Comptage Décadaire'!L:L,1,FALSE),"") | L10: =IF('Comptage Décadaire'!M11<>"",VLOOKUP('Comptage Décadaire'!M11,'Comptage Décadaire'!M:M,1,FALSE),"") | M10: =IF('Comptage Décadaire'!N11<>"",VLOOKUP('Comptage Décadaire'!N11,Utilisateurs!$D:$F,3,FALSE),"") | N10: =IF('Comptage Décadaire'!O11<>"",VLOOKUP('Comptage Décadaire'!O11,Utilisateurs!$D:$F,3,FALSE),"") | O10: =IF('Comptage Décadaire'!P11<>"",VLOOKUP('Comptage Décadaire'!P11,Utilisateurs!$D:$F,3,FALSE),"") | P10: =IF('Comptage Décadaire'!Q11<>"",VLOOKUP('Comptage Décadaire'!Q11,Utilisateurs!$D:$F,3,FALSE),"") | Q10: =IF('Comptage Décadaire'!R11<>"",VLOOKUP('Comptage Décadaire'!R11,Utilisateurs!$D:$F,3,FALSE),"") | R10: =IF('Comptage Décadaire'!S11<>"",VLOOKUP('Comptage Décadaire'!S11,Nomenclature!$N:$O,2,FALSE),"") | S10: =IF('Comptage Décadaire'!T11<>"",VLOOKUP('Comptage Décadaire'!T11,'Comptage Décadaire'!T:T,1,FALSE),"") | T10: =IF('Comptage Décadaire'!U11<>"",VLOOKUP('Comptage Décadaire'!U11,'Comptage Décadaire'!U:U,1,FALSE),"") | U10: =IF('Comptage Décadaire'!V11<>"",VLOOKUP('Comptage Décadaire'!V11,'Comptage Décadaire'!V:V,1,FALSE),"") | V10: =IF('Comptage Décadaire'!W11<>"",VLOOKUP('Comptage Décadaire'!W11,'Comptage Décadaire'!W:W,1,FALSE),"") | W10: =IF('Comptage Décadaire'!X11<>"",VLOOKUP('Comptage Décadaire'!X11,'Comptage Décadaire'!X:X,1,FALSE),"") | X10: =IF('Comptage Décadaire'!Y11<>"",VLOOKUP('Comptage Décadaire'!Y11,'Comptage Décadaire'!Y:Y,1,FALSE),"") | Y10: =IF('Comptage Décadaire'!Z11<>"",VLOOKUP('Comptage Décadaire'!Z11,Nomenclature!$F$2:$G$7,2,FALSE),"") | Z10: =IF('Comptage Décadaire'!AA11<>"",VLOOKUP('Comptage Décadaire'!AA11,Nomenclature!$H$2:$I$31,2,FALSE),"") | AA10: =IF('Comptage Décadaire'!AB11<>"",VLOOKUP('Comptage Décadaire'!AB11,Nomenclature!$J$2:$K$21,2,FALSE),"") | AB10: =IF('Comptage Décadaire'!AC11<>"",VLOOKUP('Comptage Décadaire'!AC11,'Comptage Décadaire'!AC:AC,1,FALSE),"") | AC10: =IF('Comptage Décadaire'!AD11<>"",VLOOKUP('Comptage Décadaire'!AD11,Nomenclature!$L$2:$M$8,2,FALSE),"") | AD10: =IF('Comptage Décadaire'!AE11<>"",VLOOKUP('Comptage Décadaire'!AE11,Utilisateurs!$D$2:$F$81,3,FALSE),"") | AE10: =IF('Comptage Décadaire'!AF11<>"",VLOOKUP('Comptage Décadaire'!AF11,'Comptage Décadaire'!AF:AF,1,FALSE),"") | AF10: =IF('Comptage Décadaire'!AG11<>"",VLOOKUP('Comptage Décadaire'!AG11,'Comptage Décadaire'!AG:AG,1,FALSE),"")
A11: =IF('Comptage Décadaire'!A12<>"",VLOOKUP('Comptage Décadaire'!A12,'Comptage Décadaire'!A:A,1,FALSE),"") | B11: =IF('Comptage Décadaire'!B12<>"",VLOOKUP('Comptage Décadaire'!B12,'Comptage Décadaire'!B:B,1,FALSE),"") | C11: =IF('Comptage Décadaire'!C12<>"",VLOOKUP('Comptage Décadaire'!C12,'Comptage Décadaire'!C:C,1,FALSE),"") | D11: =IF('Comptage Décadaire'!D12<>"",VLOOKUP('Comptage Décadaire'!D12,Sites!$A:$B,2,FALSE),"") | E11: =IF('Comptage Décadaire'!E12<>"",VLOOKUP('Comptage Décadaire'!E12,'Comptage Décadaire'!E:E,1,FALSE),"") | F11: =IF('Comptage Décadaire'!F12<>"",VLOOKUP('Comptage Décadaire'!F12,Nomenclature!$B$2:$C$4,2,FALSE),"") | G11: =IF('Comptage Décadaire'!G12<>"",VLOOKUP('Comptage Décadaire'!G12,'Comptage Décadaire'!G:G,1,FALSE),"") | H11: =IF('Comptage Décadaire'!H12<>"",VLOOKUP('Comptage Décadaire'!H12,Nomenclature!$D$2:$E$7,2,FALSE),"") | I11: =IF('Comptage Décadaire'!J12<>"",VLOOKUP('Comptage Décadaire'!J12,'Comptage Décadaire'!J:J,1,FALSE),"") | J11: =IF('Comptage Décadaire'!K12<>"",VLOOKUP('Comptage Décadaire'!K12,'Comptage Décadaire'!K:K,1,FALSE),"") | K11: =IF('Comptage Décadaire'!L12<>"",VLOOKUP('Comptage Décadaire'!L12,'Comptage Décadaire'!L:L,1,FALSE),"") | L11: =IF('Comptage Décadaire'!M12<>"",VLOOKUP('Comptage Décadaire'!M12,'Comptage Décadaire'!M:M,1,FALSE),"") | M11: =IF('Comptage Décadaire'!N12<>"",VLOOKUP('Comptage Décadaire'!N12,Utilisateurs!$D:$F,3,FALSE),"") | N11: =IF('Comptage Décadaire'!O12<>"",VLOOKUP('Comptage Décadaire'!O12,Utilisateurs!$D:$F,3,FALSE),"") | O11: =IF('Comptage Décadaire'!P12<>"",VLOOKUP('Comptage Décadaire'!P12,Utilisateurs!$D:$F,3,FALSE),"") | P11: =IF('Comptage Décadaire'!Q12<>"",VLOOKUP('Comptage Décadaire'!Q12,Utilisateurs!$D:$F,3,FALSE),"") | Q11: =IF('Comptage Décadaire'!R12<>"",VLOOKUP('Comptage Décadaire'!R12,Utilisateurs!$D:$F,3,FALSE),"") | R11: =IF('Comptage Décadaire'!S12<>"",VLOOKUP('Comptage Décadaire'!S12,Nomenclature!$N:$O,2,FALSE),"") | S11: =IF('Comptage Décadaire'!T12<>"",VLOOKUP('Comptage Décadaire'!T12,'Comptage Décadaire'!T:T,1,FALSE),"") | T11: =IF('Comptage Décadaire'!U12<>"",VLOOKUP('Comptage Décadaire'!U12,'Comptage Décadaire'!U:U,1,FALSE),"") | U11: =IF('Comptage Décadaire'!V12<>"",VLOOKUP('Comptage Décadaire'!V12,'Comptage Décadaire'!V:V,1,FALSE),"") | V11: =IF('Comptage Décadaire'!W12<>"",VLOOKUP('Comptage Décadaire'!W12,'Comptage Décadaire'!W:W,1,FALSE),"") | W11: =IF('Comptage Décadaire'!X12<>"",VLOOKUP('Comptage Décadaire'!X12,'Comptage Décadaire'!X:X,1,FALSE),"") | X11: =IF('Comptage Décadaire'!Y12<>"",VLOOKUP('Comptage Décadaire'!Y12,'Comptage Décadaire'!Y:Y,1,FALSE),"") | Y11: =IF('Comptage Décadaire'!Z12<>"",VLOOKUP('Comptage Décadaire'!Z12,Nomenclature!$F$2:$G$7,2,FALSE),"") | Z11: =IF('Comptage Décadaire'!AA12<>"",VLOOKUP('Comptage Décadaire'!AA12,Nomenclature!$H$2:$I$31,2,FALSE),"") | AA11: =IF('Comptage Décadaire'!AB12<>"",VLOOKUP('Comptage Décadaire'!AB12,Nomenclature!$J$2:$K$21,2,FALSE),"") | AB11: =IF('Comptage Décadaire'!AC12<>"",VLOOKUP('Comptage Décadaire'!AC12,'Comptage Décadaire'!AC:AC,1,FALSE),"") | AC11: =IF('Comptage Décadaire'!AD12<>"",VLOOKUP('Comptage Décadaire'!AD12,Nomenclature!$L$2:$M$8,2,FALSE),"") | AD11: =IF('Comptage Décadaire'!AE12<>"",VLOOKUP('Comptage Décadaire'!AE12,Utilisateurs!$D$2:$F$81,3,FALSE),"") | AE11: =IF('Comptage Décadaire'!AF12<>"",VLOOKUP('Comptage Décadaire'!AF12,'Comptage Décadaire'!AF:AF,1,FALSE),"") | AF11: =IF('Comptage Décadaire'!AG12<>"",VLOOKUP('Comptage Décadaire'!AG12,'Comptage Décadaire'!AG:AG,1,FALSE),"")
A12: =IF('Comptage Décadaire'!A13<>"",VLOOKUP('Comptage Décadaire'!A13,'Comptage Décadaire'!A:A,1,FALSE),"") | B12: =IF('Comptage Décadaire'!B13<>"",VLOOKUP('Comptage Décadaire'!B13,'Comptage Décadaire'!B:B,1,FALSE),"") | C12: =IF('Comptage Décadaire'!C13<>"",VLOOKUP('Comptage Décadaire'!C13,'Comptage Décadaire'!C:C,1,FALSE),"") | D12: =IF('Comptage Décadaire'!D13<>"",VLOOKUP('Comptage Décadaire'!D13,Sites!$A:$B,2,FALSE),"") | E12: =IF('Comptage Décadaire'!E13<>"",VLOOKUP('Comptage Décadaire'!E13,'Comptage Décadaire'!E:E,1,FALSE),"") | F12: =IF('Comptage Décadaire'!F13<>"",VLOOKUP('Comptage Décadaire'!F13,Nomenclature!$B$2:$C$4,2,FALSE),"") | G12: =IF('Comptage Décadaire'!G13<>"",VLOOKUP('Comptage Décadaire'!G13,'Comptage Décadaire'!G:G,1,FALSE),"") | H12: =IF('Comptage Décadaire'!H13<>"",VLOOKUP('Comptage Décadaire'!H13,Nomenclature!$D$2:$E$7,2,FALSE),"") | I12: =IF('Comptage Décadaire'!J13<>"",VLOOKUP('Comptage Décadaire'!J13,'Comptage Décadaire'!J:J,1,FALSE),"") | J12: =IF('Comptage Décadaire'!K13<>"",VLOOKUP('Comptage Décadaire'!K13,'Comptage Décadaire'!K:K,1,FALSE),"") | K12: =IF('Comptage Décadaire'!L13<>"",VLOOKUP('Comptage Décadaire'!L13,'Comptage Décadaire'!L:L,1,FALSE),"") | L12: =IF('Comptage Décadaire'!M13<>"",VLOOKUP('Comptage Décadaire'!M13,'Comptage Décadaire'!M:M,1,FALSE),"") | M12: =IF('Comptage Décadaire'!N13<>"",VLOOKUP('Comptage Décadaire'!N13,Utilisateurs!$D:$F,3,FALSE),"") | N12: =IF('Comptage Décadaire'!O13<>"",VLOOKUP('Comptage Décadaire'!O13,Utilisateurs!$D:$F,3,FALSE),"") | O12: =IF('Comptage Décadaire'!P13<>"",VLOOKUP('Comptage Décadaire'!P13,Utilisateurs!$D:$F,3,FALSE),"") | P12: =IF('Comptage Décadaire'!Q13<>"",VLOOKUP('Comptage Décadaire'!Q13,Utilisateurs!$D:$F,3,FALSE),"") | Q12: =IF('Comptage Décadaire'!R13<>"",VLOOKUP('Comptage Décadaire'!R13,Utilisateurs!$D:$F,3,FALSE),"") | R12: =IF('Comptage Décadaire'!S13<>"",VLOOKUP('Comptage Décadaire'!S13,Nomenclature!$N:$O,2,FALSE),"") | S12: =IF('Comptage Décadaire'!T13<>"",VLOOKUP('Comptage Décadaire'!T13,'Comptage Décadaire'!T:T,1,FALSE),"") | T12: =IF('Comptage Décadaire'!U13<>"",VLOOKUP('Comptage Décadaire'!U13,'Comptage Décadaire'!U:U,1,FALSE),"") | U12: =IF('Comptage Décadaire'!V13<>"",VLOOKUP('Comptage Décadaire'!V13,'Comptage Décadaire'!V:V,1,FALSE),"") | V12: =IF('Comptage Décadaire'!W13<>"",VLOOKUP('Comptage Décadaire'!W13,'Comptage Décadaire'!W:W,1,FALSE),"") | W12: =IF('Comptage Décadaire'!X13<>"",VLOOKUP('Comptage Décadaire'!X13,'Comptage Décadaire'!X:X,1,FALSE),"") | X12: =IF('Comptage Décadaire'!Y13<>"",VLOOKUP('Comptage Décadaire'!Y13,'Comptage Décadaire'!Y:Y,1,FALSE),"") | Y12: =IF('Comptage Décadaire'!Z13<>"",VLOOKUP('Comptage Décadaire'!Z13,Nomenclature!$F$2:$G$7,2,FALSE),"") | Z12: =IF('Comptage Décadaire'!AA13<>"",VLOOKUP('Comptage Décadaire'!AA13,Nomenclature!$H$2:$I$31,2,FALSE),"") | AA12: =IF('Comptage Décadaire'!AB13<>"",VLOOKUP('Comptage Décadaire'!AB13,Nomenclature!$J$2:$K$21,2,FALSE),"") | AB12: =IF('Comptage Décadaire'!AC13<>"",VLOOKUP('Comptage Décadaire'!AC13,'Comptage Décadaire'!AC:AC,1,FALSE),"") | AC12: =IF('Comptage Décadaire'!AD13<>"",VLOOKUP('Comptage Décadaire'!AD13,Nomenclature!$L$2:$M$8,2,FALSE),"") | AD12: =IF('Comptage Décadaire'!AE13<>"",VLOOKUP('Comptage Décadaire'!AE13,Utilisateurs!$D$2:$F$81,3,FALSE),"") | AE12: =IF('Comptage Décadaire'!AF13<>"",VLOOKUP('Comptage Décadaire'!AF13,'Comptage Décadaire'!AF:AF,1,FALSE),"") | AF12: =IF('Comptage Décadaire'!AG13<>"",VLOOKUP('Comptage Décadaire'!AG13,'Comptage Décadaire'!AG:AG,1,FALSE),"")
A13: =IF('Comptage Décadaire'!A14<>"",VLOOKUP('Comptage Décadaire'!A14,'Comptage Décadaire'!A:A,1,FALSE),"") | B13: =IF('Comptage Décadaire'!B14<>"",VLOOKUP('Comptage Décadaire'!B14,'Comptage Décadaire'!B:B,1,FALSE),"") | C13: =IF('Comptage Décadaire'!C14<>"",VLOOKUP('Comptage Décadaire'!C14,'Comptage Décadaire'!C:C,1,FALSE),"") | D13: =IF('Comptage Décadaire'!D14<>"",VLOOKUP('Comptage Décadaire'!D14,Sites!$A:$B,2,FALSE),"") | E13: =IF('Comptage Décadaire'!E14<>"",VLOOKUP('Comptage Décadaire'!E14,'Comptage Décadaire'!E:E,1,FALSE),"") | F13: =IF('Comptage Décadaire'!F14<>"",VLOOKUP('Comptage Décadaire'!F14,Nomenclature!$B$2:$C$4,2,FALSE),"") | G13: =IF('Comptage Décadaire'!G14<>"",VLOOKUP('Comptage Décadaire'!G14,'Comptage Décadaire'!G:G,1,FALSE),"") | H13: =IF('Comptage Décadaire'!H14<>"",VLOOKUP('Comptage Décadaire'!H14,Nomenclature!$D$2:$E$7,2,FALSE),"") | I13: =IF('Comptage Décadaire'!J14<>"",VLOOKUP('Comptage Décadaire'!J14,'Comptage Décadaire'!J:J,1,FALSE),"") | J13: =IF('Comptage Décadaire'!K14<>"",VLOOKUP('Comptage Décadaire'!K14,'Comptage Décadaire'!K:K,1,FALSE),"") | K13: =IF('Comptage Décadaire'!L14<>"",VLOOKUP('Comptage Décadaire'!L14,'Comptage Décadaire'!L:L,1,FALSE),"") | L13: =IF('Comptage Décadaire'!M14<>"",VLOOKUP('Comptage Décadaire'!M14,'Comptage Décadaire'!M:M,1,FALSE),"") | M13: =IF('Comptage Décadaire'!N14<>"",VLOOKUP('Comptage Décadaire'!N14,Utilisateurs!$D:$F,3,FALSE),"") | N13: =IF('Comptage Décadaire'!O14<>"",VLOOKUP('Comptage Décadaire'!O14,Utilisateurs!$D:$F,3,FALSE),"") | O13: =IF('Comptage Décadaire'!P14<>"",VLOOKUP('Comptage Décadaire'!P14,Utilisateurs!$D:$F,3,FALSE),"") | P13: =IF('Comptage Décadaire'!Q14<>"",VLOOKUP('Comptage Décadaire'!Q14,Utilisateurs!$D:$F,3,FALSE),"") | Q13: =IF('Comptage Décadaire'!R14<>"",VLOOKUP('Comptage Décadaire'!R14,Utilisateurs!$D:$F,3,FALSE),"") | R13: =IF('Comptage Décadaire'!S14<>"",VLOOKUP('Comptage Décadaire'!S14,Nomenclature!$N:$O,2,FALSE),"") | S13: =IF('Comptage Décadaire'!T14<>"",VLOOKUP('Comptage Décadaire'!T14,'Comptage Décadaire'!T:T,1,FALSE),"") | T13: =IF('Comptage Décadaire'!U14<>"",VLOOKUP('Comptage Décadaire'!U14,'Comptage Décadaire'!U:U,1,FALSE),"") | U13: =IF('Comptage Décadaire'!V14<>"",VLOOKUP('Comptage Décadaire'!V14,'Comptage Décadaire'!V:V,1,FALSE),"") | V13: =IF('Comptage Décadaire'!W14<>"",VLOOKUP('Comptage Décadaire'!W14,'Comptage Décadaire'!W:W,1,FALSE),"") | W13: =IF('Comptage Décadaire'!X14<>"",VLOOKUP('Comptage Décadaire'!X14,'Comptage Décadaire'!X:X,1,FALSE),"") | X13: =IF('Comptage Décadaire'!Y14<>"",VLOOKUP('Comptage Décadaire'!Y14,'Comptage Décadaire'!Y:Y,1,FALSE),"") | Y13: =IF('Comptage Décadaire'!Z14<>"",VLOOKUP('Comptage Décadaire'!Z14,Nomenclature!$F$2:$G$7,2,FALSE),"") | Z13: =IF('Comptage Décadaire'!AA14<>"",VLOOKUP('Comptage Décadaire'!AA14,Nomenclature!$H$2:$I$31,2,FALSE),"") | AA13: =IF('Comptage Décadaire'!AB14<>"",VLOOKUP('Comptage Décadaire'!AB14,Nomenclature!$J$2:$K$21,2,FALSE),"") | AB13: =IF('Comptage Décadaire'!AC14<>"",VLOOKUP('Comptage Décadaire'!AC14,'Comptage Décadaire'!AC:AC,1,FALSE),"") | AC13: =IF('Comptage Décadaire'!AD14<>"",VLOOKUP('Comptage Décadaire'!AD14,Nomenclature!$L$2:$M$8,2,FALSE),"") | AD13: =IF('Comptage Décadaire'!AE14<>"",VLOOKUP('Comptage Décadaire'!AE14,Utilisateurs!$D$2:$F$81,3,FALSE),"") | AE13: =IF('Comptage Décadaire'!AF14<>"",VLOOKUP('Comptage Décadaire'!AF14,'Comptage Décadaire'!AF:AF,1,FALSE),"") | AF13: =IF('Comptage Décadaire'!AG14<>"",VLOOKUP('Comptage Décadaire'!AG14,'Comptage Décadaire'!AG:AG,1,FALSE),"")
... A170: =IF('Comptage Décadaire'!A171<>"",VLOOKUP('Comptage Décadaire'!A171,'Comptage Décadaire'!A:A,1,FALSE),"") | B170: =IF('Comptage Décadaire'!B171<>"",VLOOKUP('Comptage Décadaire'!B171,'Comptage Décadaire'!B:B,1,FALSE),"") | C170: =IF('Comptage Décadaire'!C171<>"",VLOOKUP('Comptage Décadaire'!C171,'Comptage Décadaire'!C:C,1,FALSE),"") | D170: =IF('Comptage Décadaire'!D171<>"",VLOOKUP('Comptage Décadaire'!D171,Sites!$A:$B,2,FALSE),"") | E170: =IF('Comptage Décadaire'!E171<>"",VLOOKUP('Comptage Décadaire'!E171,'Comptage Décadaire'!E:E,1,FALSE),"") | F170: =IF('Comptage Décadaire'!F171<>"",VLOOKUP('Comptage Décadaire'!F171,Nomenclature!$B$2:$C$4,2,FALSE),"") | G170: =IF('Comptage Décadaire'!G171<>"",VLOOKUP('Comptage Décadaire'!G171,'Comptage Décadaire'!G:G,1,FALSE),"") | H170: =IF('Comptage Décadaire'!H171<>"",VLOOKUP('Comptage Décadaire'!H171,Nomenclature!$D$2:$E$7,2,FALSE),"") | I170: =IF('Comptage Décadaire'!J171<>"",VLOOKUP('Comptage Décadaire'!J171,'Comptage Décadaire'!J:J,1,FALSE),"") | J170: =IF('Comptage Décadaire'!K171<>"",VLOOKUP('Comptage Décadaire'!K171,'Comptage Décadaire'!K:K,1,FALSE),"") | K170: =IF('Comptage Décadaire'!L171<>"",VLOOKUP('Comptage Décadaire'!L171,'Comptage Décadaire'!L:L,1,FALSE),"") | L170: =IF('Comptage Décadaire'!M171<>"",VLOOKUP('Comptage Décadaire'!M171,'Comptage Décadaire'!M:M,1,FALSE),"") | M170: =IF('Comptage Décadaire'!N171<>"",VLOOKUP('Comptage Décadaire'!N171,Utilisateurs!$D:$F,3,FALSE),"") | N170: =IF('Comptage Décadaire'!O171<>"",VLOOKUP('Comptage Décadaire'!O171,Utilisateurs!$D:$F,3,FALSE),"") | O170: =IF('Comptage Décadaire'!P171<>"",VLOOKUP('Comptage Décadaire'!P171,Utilisateurs!$D:$F,3,FALSE),"") | P170: =IF('Comptage Décadaire'!Q171<>"",VLOOKUP('Comptage Décadaire'!Q171,Utilisateurs!$D:$F,3,FALSE),"") | Q170: =IF('Comptage Décadaire'!R171<>"",VLOOKUP('Comptage Décadaire'!R171,Utilisateurs!$D:$F,3,FALSE),"") | R170: =IF('Comptage Décadaire'!S171<>"",VLOOKUP('Comptage Décadaire'!S171,Nomenclature!$N:$O,2,FALSE),"") | S170: =IF('Comptage Décadaire'!T171<>"",VLOOKUP('Comptage Décadaire'!T171,'Comptage Décadaire'!T:T,1,FALSE),"") | T170: =IF('Comptage Décadaire'!U171<>"",VLOOKUP('Comptage Décadaire'!U171,'Comptage Décadaire'!U:U,1,FALSE),"") | U170: =IF('Comptage Décadaire'!V171<>"",VLOOKUP('Comptage Décadaire'!V171,'Comptage Décadaire'!V:V,1,FALSE),"") | V170: =IF('Comptage Décadaire'!W171<>"",VLOOKUP('Comptage Décadaire'!W171,'Comptage Décadaire'!W:W,1,FALSE),"") | W170: =IF('Comptage Décadaire'!X171<>"",VLOOKUP('Comptage Décadaire'!X171,'Comptage Décadaire'!X:X,1,FALSE),"") | X170: =IF('Comptage Décadaire'!Y171<>"",VLOOKUP('Comptage Décadaire'!Y171,'Comptage Décadaire'!Y:Y,1,FALSE),"") | Y170: =IF('Comptage Décadaire'!Z171<>"",VLOOKUP('Comptage Décadaire'!Z171,Nomenclature!$F$2:$G$7,2,FALSE),"") | Z170: =IF('Comptage Décadaire'!AA171<>"",VLOOKUP('Comptage Décadaire'!AA171,Nomenclature!$H$2:$I$31,2,FALSE),"") | AA170: =IF('Comptage Décadaire'!AB171<>"",VLOOKUP('Comptage Décadaire'!AB171,Nomenclature!$J$2:$K$21,2,FALSE),"") | AB170: =IF('Comptage Décadaire'!AC171<>"",VLOOKUP('Comptage Décadaire'!AC171,'Comptage Décadaire'!AC:AC,1,FALSE),"") | AC170: =IF('Comptage Décadaire'!AD171<>"",VLOOKUP('Comptage Décadaire'!AD171,Nomenclature!$L$2:$M$8,2,FALSE),"") | AD170: =IF('Comptage Décadaire'!AE171<>"",VLOOKUP('Comptage Décadaire'!AE171,Utilisateurs!$D$2:$F$81,3,FALSE),"") | AE170: =IF('Comptage Décadaire'!AF171<>"",VLOOKUP('Comptage Décadaire'!AF171,'Comptage Décadaire'!AF:AF,1,FALSE),"") | AF170: =IF('Comptage Décadaire'!AG171<>"",VLOOKUP('Comptage Décadaire'!AG171,'Comptage Décadaire'!AG:AG,1,FALSE),"")

Sheet Sites
A1: site_nom | B1: id_base_site | D1: SELECT s.base_site_name, s.id_base_site
A2: Anse du Galon d'or | B2: 1155 | D2: FROM gn_monitoring.t_base_sites s
A3: Arceau | B3: 1156 | D3: JOIN gn_monitoring.cor_site_module csm ON csm.id_base_site = s.id_base_site
A4: Arceau Bellevue | B4: 1157 | D4: WHERE id_module = 30 -- MULL
A5: Baie de Gatseau | B5: 1158 | D5: ORDER BY s.base_site_name;
A6: Baie de La Grognasse | B6: 1159
A7: Baie de Marécareuil | B7: 1160
A8: Baie de Saint-Lancée | B8: 1161
A9: Baie de Sinche | B9: 1162
A10: Baie du Chapus | B10: 1163
A11: Baie Sud | B11: 1164
A12: Bassin de Marennes Oléron | B12: 1165
A13: Bosse aux Écossais | B13: 1166
A14: Chenal d'Ors | B14: 1168
A15: Chez Bris Monportail Sud | B15: 1169
A16: Digue Pacaud | B16: 1170
A17: Dunes du Douhet | B17: 1171
... A128: Triangle Sud | B128: 1282

Sheet Nomenclature
B1: Type de Comptage | C1: 140 | D1: Type de dérangement | E1: 142 | F1: Precision comptage | G1: 138 | H1: Comportement | I1: 124 | J1: Code atlas | K1: 141 | L1: Statut de validation | M1: 101 | N1: Statut de l'observation | O1: 18
B2: Comptage décadaire 1 | C2: 662 | D2: Non-défini | E2: 691 | F2: Non-défini | G2: 660 | H2: Inconnu | I2: 543 | J2: Non-défini | K2: 664 | L2: Certain - très probable | M2: 314 | N2: Présent | O2: 84
B3: Comptage décadaire 2 | C3: 663 | D3: Aéronautique | E3: 686 | F3: Bonne précision | G3: 639 | H3: Accouplement | I3: 544 | J3: 1 (Nidification possible) | K3: 665 | L3: Probable | M3: 315 | N3: Non observé | O3: 83
B4: Comptage décadaire 3 | C4: 685 | D4: Balade / Promenade | E4: 687 | F4: Estimation par déduction | G4: 640 | H4: Alarme | I4: 545 | J4: 2 (Nidification possible) | K4: 666 | L4: Douteux | M4: 316
D5: Chasse | E5: 688 | F5: Ordre de grandeur | G5: 641 | H5: Attention au jeune | I5: 546 | J5: 3 (Nidification probable) | K5: 667 | L5: Invalide | M5: 317
D6: Pêcheur à pied | E6: 689 | F6: Précision < 10% | G6: 642 | H6: Chant | I6: 547 | J6: 4 (Nidification probable) | K6: 668 | L6: Non réalisable | M6: 318
D7: Prédateur | E7: 690 | F7: Sous estimation | G7: 692 | H7: Chasse/alimentation | I7: 548 | J7: 5 (Nidification probable) | K7: 669 | L7: Inconnu | M7: 319
H8: Cœur copulatoire | I8: 549 | J8: 6 (Nidification probable) | K8: 670 | L8: En attente de validation | M8: 457
H9: Construction de nid | I9: 550 | J9: 7 (Nidification probable) | K9: 671
H10: Construction de toile | I10: 551 | J10: 8 (Nidification probable) | K10: 672
H11: Défense, combat | I11: 552 | J11: 9 (Nidification probable) | K11: 673
H12: Déplacement | I12: 553 | J12: 10 (Nidification certaine) | K12: 674
H13: Dortoir | I13: 554 | J13: 11 (Nidification certaine) | K13: 675
H14: Echouage | I14: 555 | J14: 12 (Nidification certaine) | K14: 676
H15: Erratique | I15: 556 | J15: 13 (Nidification certaine) | K15: 677
H16: Estivage | I16: 557 | J16: 14 (Nidification certaine) | K16: 678
H17: Fuite | I17: 558 | J17: 15 (Nidification certaine) | K17: 679
H18: Halte migratoire | I18: 559 | J18: 16 (Nidification certaine) | K18: 680
H19: Hivernage | I19: 560 | J19: 30 - Nidification possible (défaut) | K19: 681
H20: Migration | I20: 561 | J20: 40 - Nidification probable (défaut) | K20: 682
H21: Non renseigné | I21: 562 | J21: 50 - Nidification certaine (défaut) | K21: 683
H22: Nourrissage des jeunes | I22: 563
H23: Passage en vol | I23: 564
H24: Pond | I24: 565
H25: Posé | I25: 566
H26: Repos | I26: 650
H27: Sédentaire | I27: 651
H28: Swarming | I28: 652
H29: Tandem | I29: 653
H30: Territorial | I30: 654
H31: Thermorégulation | I31: 655

Sheet Utilisateurs
A1: id_role | B1: nom_role | C1: prenom_role | D1: nom_prenom_role | E1: nom_organisme | F1: id_role | H1: SELECT r.id_role, r.nom_role, r.prenom_role, TRIM(CONCAT(TRIM(r.nom_role), ' ', TRIM(r.prenom_role))) as nom_prenom_role, org.nom_organisme, r.id_role
A2: 357 | B2: Bénévole | C2: LPO/RN | D2: Bénévole LPO/RN | E2: LPO | F2: 357 | H2: FROM utilisateurs.t_roles r
A3: 10 | B3: ROBIN | C3: Frédéric | D3: ROBIN Frédéric | E3: LPO | F3: 10 | H3: JOIN utilisateurs.bib_organismes org ON org.id_organisme = r.id_organisme
A4: 17 | B4: TOMA | C4: Maxime | D4: TOMA Maxime | E4: LPO | F4: 17 | H4: JOIN utilisateurs.cor_roles cr ON r.id_role = cr.id_role_utilisateur
H5: WHERE id_role_groupe IN (9,405,404) AND id_role != 1
H6: ORDER BY org.id_organisme, nom_prenom_role;

Sheet Taxons
A1: Nom scientifique | B1: Nom vernaculaire | C1: Code MNHN | E1: SELECT DISTINCT tx.nom_valide, tx.nom_vern, tx.cd_ref
A2: Acanthis flammea cabaret (Muller, 1776) | B2: Sizerin cabaret | C2: 886230 | E2: FROM taxonomie.bib_noms bn
A3: Acanthis flammea (Linnaeus, 1758) | B3: Sizerin flammé | C3: 4597 | E3: JOIN taxonomie.taxref tx ON bn.cd_nom = tx.cd_nom
A4: Accipiter gentilis (Linnaeus, 1758) | B4: Autour des palombes | C4: 2891 | E4: WHERE classe = 'Aves' OR tx.cd_ref = 100000000
A5: Accipiter nisus (Linnaeus, 1758) | B5: Épervier d'Europe | C5: 2895 | E5: ORDER BY tx.nom_valide;
A6: Acrocephalus agricola (Jerdon, 1845) | B6: Rousserolle isabelle | C6: 199459
A7: Acrocephalus arundinaceus (Linnaeus, 1758) | B7: Rousserolle turdoïde | C7: 4198
A8: Acrocephalus dumetorum Blyth, 1849 | B8: Rousserolle des buissons | C8: 4190
A9: Acrocephalus J. A. Naumann & J. F. Naumann, 1811 | C9: 188772
A10: Acrocephalus melanopogon (Temminck, 1823) | B10: Lusciniole à moustaches | C10: 4180
A11: Acrocephalus paludicola (Vieillot, 1817) | B11: Phragmite aquatique | C11: 4184
A12: Acrocephalus palustris (Bechstein, 1798) | B12: Rousserolle verderolle | C12: 4192
A13: Acrocephalus schoenobaenus (Linnaeus, 1758) | B13: Phragmite des joncs | C13: 4187
A14: Acrocephalus scirpaceus (Hermann, 1804) | B14: Rousserolle effarvatte | C14: 4195
A15: Actitis hypoleucos (Linnaeus, 1758) | B15: Chevalier guignette | C15: 2616
A16: Actitis Illiger, 1811 | C16: 188807
A17: Aegithalos caudatus (Linnaeus, 1758) | B17: Mésange à longue queue, Orite à longue queue | C17: 4342
A18: Aix galericulata (Linnaeus, 1758) | B18: Canard mandarin | C18: 2776
A19: Aix sponsa (Linnaeus, 1758) | B19: Canard carolin, Canard branchu | C19: 2775
A20: Alauda arvensis Linnaeus, 1758 | B20: Alouette des champs | C20: 3676
A21: Alca torda Linnaeus, 1758 | B21: Petit pingouin, Pingouin torda | C21: 3388
A22: Alcedo atthis (Linnaeus, 1758) | B22: Martin-pêcheur d'Europe | C22: 3571
A23: Alcidae Leach, 1820 | B23: Macareux, Guillemots, Pingouins | C23: 185996
A24: Alectoris rufa (Linnaeus, 1758) | B24: Perdrix rouge | C24: 2975
A25: Alle alle (Linnaeus, 1758) | B25: Mergule nain | C25: 3396
A26: Alopochen aegyptiaca (Linnaeus, 1766) | B26: Ouette d'Égypte, Oie d'Égypte | C26: 459626
A27: Anas acuta Linnaeus, 1758 | B27: Canard pilet | C27: 1973
A28: Anas bahamensis Linnaeus, 1758 | B28: Canard des Bahamas, Pilet des Bahamas | C28: 1948
... A31: Anas crecca Linnaeus, 1758 | B31: Sarcelle d'hiver | C31: 1958
A32: Anas Linnaeus, 1758 | C32: 189130
A33: Anas platyrhynchos Linnaeus, 1758 | B33: Canard colvert | C33: 1966
A34: Anas sibilatrix Poeppig, 1829 | C34: 933144
A35: Anatidae Leach, 1820 | C35: 185967
A36: Anser albifrons (Scopoli, 1769) | B36: Oie rieuse | C36: 2734
A37: Anser anser (Linnaeus, 1758) | B37: Oie cendrée | C37: 2741
A38: Anser anser rubrirostris Swinhoe, 1871 | C38: 2745
A39: Anser brachyrhynchus (Baillon, 1833) | B39: Oie à bec court | C39: 2725
A40: Anser Brisson, 1760 | C40: 189224
A41: Anser caerulescens (Linnaeus, 1758) | B41: Oie des neiges | C41: 2727
A42: Anser erythropus (Linnaeus, 1758) | B42: Oie naine | C42: 2739
...
